Traceback (most recent call last):
  File "/home/tin/.local/bin/mapbox", line 11, in <module>
    sys.exit(main_group())
  File "/home/tin/anaconda3/lib/python3.6/site-packages/click/core.py", line 764, in __call__
    return self.main(*args, **kwargs)
  File "/home/tin/anaconda3/lib/python3.6/site-packages/click/core.py", line 717, in main
    rv = self.invoke(ctx)
  File "/home/tin/anaconda3/lib/python3.6/site-packages/click/core.py", line 1137, in invoke
    return _process_result(sub_ctx.command.invoke(sub_ctx))
  File "/home/tin/anaconda3/lib/python3.6/site-packages/click/core.py", line 956, in invoke
    return ctx.invoke(self.callback, **ctx.params)
  File "/home/tin/anaconda3/lib/python3.6/site-packages/click/core.py", line 555, in invoke
    return callback(*args, **kwargs)
  File "/home/tin/anaconda3/lib/python3.6/site-packages/click/decorators.py", line 17, in new_func
    return f(get_current_context(), *args, **kwargs)
  File "/home/tin/.local/lib/python3.6/site-packages/mapboxcli/scripts/uploads.py", line 71, in upload
    callback=callback)
  File "/home/tin/.local/lib/python3.6/site-packages/mapbox/services/uploads.py", line 276, in upload
    tileset = self._validate_tileset(tileset)
  File "/home/tin/.local/lib/python3.6/site-packages/mapbox/services/uploads.py", line 64, in _validate_tileset
    tileset, pattern))
mapbox.errors.ValidationError: tileset tin117.DAC-topo3JulNOxS+Al is invalid, must match r"^[a-z0-9-_]{1,32}\.[a-z0-9-_]{1,32}$"
--FAIL-- 0: upload of DAC-topo3JulNOxS+Al.geojson failed with exit code 1

==== above failed cuz had + in filename.  fixed ====

{"id":"ck5lvbmg61j3f2oql8wkzheqs","name":"DAC-topo3JulNOxSpAl","complete":false,"error":null,"created":"2020-01-20T03:06:34.012Z","modified":"2020-01-20T03:06:34.012Z","tileset":"tin117.DAC-topo3JulNOxSpAl","owner":"tin117","progress":0}
++ OK ++ 0: upload of DAC-topo3JulNOxSpAl.geojson completed successfully.
